mplus_output/uni-25-SHARE_W2.out
Mplus VERSION 8.1 (Mac)
MUTHEN & MUTHEN
05/27/2020  10:28 PM

INPUT INSTRUCTIONS

  DATA:
  FILE = "uni-25-SHARE_W2.dat";

  VARIABLE:
  NAMES = mplusid UDAT UDAY UMON UYER UIWR UDWR UANI URE3 URE4 URE6;
   MISSING=.;
   CATEGORICAL ARE all; idvariable = mplusid;
  ANALYSIS:
  estimator = wlsmv; coverage=0;
  MODEL:
  g by UDAT * ;
   g by UDAY * ;
   g by UMON * ;
   g by UYER * ;
   g by UIWR * ;
   g by UDWR * ;
   g by URE3 * ;
   g by URE6 * ;
   g by UANI * ;
   g by URE4 * ;
   g @ 1;

  OUTPUT:
  standardized; svalues;



*** WARNING
  Data set contains cases with missing on all variables.
  These cases were not included in the analysis.
  Number of cases with missing on all variables:  618
   1 WARNING(S) FOUND IN THE INPUT INSTRUCTIONS




SUMMARY OF ANALYSIS

Number of groups                                                 1
Number of observations                                       36565

Number of dependent variables                                   10
Number of independent variables                                  0
Number of continuous latent variables                            1

Observed dependent variables

  Binary and ordered categorical (ordinal)
   UDAT        UDAY        UMON        UYER        UIWR        UDWR
   UANI        URE3        URE4        URE6

Continuous latent variables
   G

Variables with special functions

  ID variable           MPLUSID

Estimator                                                    WLSMV
Maximum number of iterations                                  1000
Convergence criterion                                    0.500D-04
Maximum number of steepest descent iterations                   20
Maximum number of iterations for H1                           2000
Convergence criterion for H1                             0.100D-03
Parameterization                                             DELTA
Link                                                        PROBIT

Input data file(s)
  uni-25-SHARE_W2.dat

Input data format  FREE


SUMMARY OF DATA

     Number of missing data patterns            62


COVARIANCE COVERAGE OF DATA

Minimum covariance coverage value   0.000


     PROPORTION OF DATA PRESENT


           Covariance Coverage
              UDAT          UDAY          UMON          UYER          UIWR
              ________      ________      ________      ________      ________
 UDAT           0.993
 UDAY           0.993         0.995
 UMON           0.993         0.994         0.995
 UYER           0.992         0.994         0.994         0.994
 UIWR           0.989         0.991         0.991         0.990         0.996
 UDWR           0.989         0.991         0.991         0.991         0.996
 UANI           0.985         0.987         0.987         0.986         0.987
 URE3           0.832         0.833         0.833         0.833         0.832
 URE4           0.673         0.673         0.673         0.673         0.672
 URE6           0.434         0.434         0.434         0.434         0.433


           Covariance Coverage
              UDWR          UANI          URE3          URE4          URE6
              ________      ________      ________      ________      ________
 UDWR           0.996
 UANI           0.987         0.989
 URE3           0.832         0.831         0.833
 URE4           0.673         0.672         0.673         0.673
 URE6           0.434         0.433         0.434         0.434         0.434


UNIVARIATE PROPORTIONS AND COUNTS FOR CATEGORICAL VARIABLES

    UDAT
      Category 1    0.114         4134.000
      Category 2    0.886        32173.000
    UDAY
      Category 1    0.029         1056.000
      Category 2    0.971        35320.000
    UMON
      Category 1    0.020          738.000
      Category 2    0.980        35630.000
    UYER
      Category 1    0.021          779.000
      Category 2    0.979        35574.000
    UIWR
      Category 1    0.022          787.000
      Category 2    0.023          821.000
      Category 3    0.046         1672.000
      Category 4    0.104         3796.000
      Category 5    0.185         6738.000
      Category 6    0.429        15627.000
      Category 7    0.121         4403.000
      Category 8    0.052         1875.000
      Category 9    0.015          552.000
      Category 10    0.004          135.000
    UDWR
      Category 1    0.097         3545.000
      Category 2    0.074         2678.000
      Category 3    0.124         4508.000
      Category 4    0.191         6947.000
      Category 5    0.199         7260.000
      Category 6    0.244         8892.000
      Category 7    0.043         1577.000
      Category 8    0.018          655.000
      Category 9    0.007          255.000
      Category 10    0.003          103.000
    UANI
      Category 1    0.006          233.000
      Category 2    0.014          519.000
      Category 3    0.066         2368.000
      Category 4    0.159         5747.000
      Category 5    0.222         8010.000
      Category 6    0.208         7536.000
      Category 7    0.159         5760.000
      Category 8    0.087         3127.000
      Category 9    0.045         1628.000
      Category 10    0.034         1218.000
    URE3
      Category 1    0.063         1931.000
      Category 2    0.937        28522.000
    URE4
      Category 1    0.289         7106.000
      Category 2    0.711        17517.000
    URE6
      Category 1    0.587         9319.000
      Category 2    0.413         6547.000


     WARNING:  THE BIVARIATE TABLE OF URE4 AND URE3 HAS AN EMPTY CELL.

     WARNING:  THE BIVARIATE TABLE OF URE4 AND URE3 HAS AN EMPTY CELL.

     WARNING:  THE BIVARIATE TABLE OF URE6 AND URE3 HAS AN EMPTY CELL.

     WARNING:  THE BIVARIATE TABLE OF URE6 AND URE3 HAS AN EMPTY CELL.

     WARNING:  THE BIVARIATE TABLE OF URE6 AND URE4 HAS AN EMPTY CELL.

     WARNING:  THE BIVARIATE TABLE OF URE6 AND URE4 HAS AN EMPTY CELL.


THE MODEL ESTIMATION TERMINATED NORMALLY



MODEL FIT INFORMATION

Number of Free Parameters                       44

Chi-Square Test of Model Fit

          Value                           5366.575*
          Degrees of Freedom                    35
          P-Value                           0.0000

*   The chi-square value for MLM, MLMV, MLR, ULSMV, WLSM and WLSMV cannot be used
    for chi-square difference testing in the regular way.  MLM, MLR and WLSM
    chi-square difference testing is described on the Mplus website.  MLMV, WLSMV,
    and ULSMV difference testing is done using the DIFFTEST option.

RMSEA (Root Mean Square Error Of Approximation)

          Estimate                           0.065
          90 Percent C.I.                    0.063  0.066
          Probability RMSEA <= .05           0.000

CFI/TLI

          CFI                                0.969
          TLI                                0.961

Chi-Square Test of Model Fit for the Baseline Model

          Value                         173872.090
          Degrees of Freedom                    45
          P-Value                           0.0000

SRMR (Standardized Root Mean Square Residual)

          Value                              0.074

Optimum Function Value for Weighted Least-Squares Estimator

          Value                     0.55065799D-01



MODEL RESULTS

                                                    Two-Tailed
                    Estimate       S.E.  Est./S.E.    P-Value

 G        BY
    UDAT               0.517      0.007     71.492      0.000
    UDAY               0.729      0.010     76.075      0.000
    UMON               0.796      0.009     87.250      0.000
    UYER               0.887      0.008    115.935      0.000
    UIWR               0.875      0.002    367.432      0.000
    UDWR               0.842      0.002    347.393      0.000
    URE3               0.304      0.010     29.196      0.000
    URE6               0.198      0.009     23.125      0.000
    UANI               0.606      0.004    172.173      0.000
